2025-06-25 11:21:17,435 INFO    MainThread:3167 [wandb_setup.py:_flush():81] Current SDK version is 0.20.1
2025-06-25 11:21:17,435 INFO    MainThread:3167 [wandb_setup.py:_flush():81] Configure stats pid to 3167
2025-06-25 11:21:17,435 INFO    MainThread:3167 [wandb_setup.py:_flush():81] Loading settings from /root/.config/wandb/settings
2025-06-25 11:21:17,435 INFO    MainThread:3167 [wandb_setup.py:_flush():81] Loading settings from /root/Flappy_bird_DQN/wandb/settings
2025-06-25 11:21:17,435 INFO    MainThread:3167 [wandb_setup.py:_flush():81] Loading settings from environment variables
2025-06-25 11:21:17,436 INFO    MainThread:3167 [wandb_init.py:setup_run_log_directory():703] Logging user logs to /root/Flappy_bird_DQN/wandb/run-20250625_112117-6fssgjkt/logs/debug.log
2025-06-25 11:21:17,436 INFO    MainThread:3167 [wandb_init.py:setup_run_log_directory():704] Logging internal logs to /root/Flappy_bird_DQN/wandb/run-20250625_112117-6fssgjkt/logs/debug-internal.log
2025-06-25 11:21:17,436 INFO    MainThread:3167 [wandb_init.py:init():831] calling init triggers
2025-06-25 11:21:17,436 INFO    MainThread:3167 [wandb_init.py:init():836] wandb.init called with sweep_config: {}
config: {'learning_rate': 0.0001, 'batch_size': 32, 'gamma': 0.99, 'actions': 2, 'epsilon_start': 0.1, 'epsilon_final': 0.0001, '_wandb': {}}
2025-06-25 11:21:17,436 INFO    MainThread:3167 [wandb_init.py:init():872] starting backend
2025-06-25 11:21:17,651 INFO    MainThread:3167 [wandb_init.py:init():875] sending inform_init request
2025-06-25 11:21:17,655 INFO    MainThread:3167 [wandb_init.py:init():883] backend started and connected
2025-06-25 11:21:17,656 INFO    MainThread:3167 [wandb_init.py:init():956] updated telemetry
2025-06-25 11:21:17,662 INFO    MainThread:3167 [wandb_init.py:init():980] communicating run to backend with 90.0 second timeout
2025-06-25 11:21:48,562 INFO    Thread-1 (wrapped_target):3167 [retry.py:__call__():173] [no run ID] Retry attempt failed:
Traceback (most recent call last):
  File "/root/miniconda3/lib/python3.10/site-packages/urllib3/connection.py", line 174, in _new_conn
    conn = connection.create_connection(
  File "/root/miniconda3/lib/python3.10/site-packages/urllib3/util/connection.py", line 95, in create_connection
    raise err
  File "/root/miniconda3/lib/python3.10/site-packages/urllib3/util/connection.py", line 85, in create_connection
    sock.connect(sa)
TimeoutError: timed out

During handling of the above exception, another exception occurred:

Traceback (most recent call last):
  File "/root/miniconda3/lib/python3.10/site-packages/urllib3/connectionpool.py", line 703, in urlopen
    httplib_response = self._make_request(
  File "/root/miniconda3/lib/python3.10/site-packages/urllib3/connectionpool.py", line 386, in _make_request
    self._validate_conn(conn)
  File "/root/miniconda3/lib/python3.10/site-packages/urllib3/connectionpool.py", line 1042, in _validate_conn
    conn.connect()
  File "/root/miniconda3/lib/python3.10/site-packages/urllib3/connection.py", line 358, in connect
    self.sock = conn = self._new_conn()
  File "/root/miniconda3/lib/python3.10/site-packages/urllib3/connection.py", line 179, in _new_conn
    raise ConnectTimeoutError(
urllib3.exceptions.ConnectTimeoutError: (<urllib3.connection.HTTPSConnection object at 0x7f2530285f60>, 'Connection to api.wandb.ai timed out. (connect timeout=20)')

During handling of the above exception, another exception occurred:

Traceback (most recent call last):
  File "/root/miniconda3/lib/python3.10/site-packages/requests/adapters.py", line 667, in send
    resp = conn.urlopen(
  File "/root/miniconda3/lib/python3.10/site-packages/urllib3/connectionpool.py", line 787, in urlopen
    retries = retries.increment(
  File "/root/miniconda3/lib/python3.10/site-packages/urllib3/util/retry.py", line 592, in increment
    raise MaxRetryError(_pool, url, error or ResponseError(cause))
urllib3.exceptions.MaxRetryError: HTTPSConnectionPool(host='api.wandb.ai', port=443): Max retries exceeded with url: /graphql (Caused by ConnectTimeoutError(<urllib3.connection.HTTPSConnection object at 0x7f2530285f60>, 'Connection to api.wandb.ai timed out. (connect timeout=20)'))

During handling of the above exception, another exception occurred:

Traceback (most recent call last):
  File "/root/miniconda3/lib/python3.10/site-packages/wandb/sdk/lib/retry.py", line 134, in __call__
    result = self._call_fn(*args, **kwargs)
  File "/root/miniconda3/lib/python3.10/site-packages/wandb/sdk/internal/internal_api.py", line 396, in execute
    return self.client.execute(*args, **kwargs)  # type: ignore
  File "/root/miniconda3/lib/python3.10/site-packages/wandb/vendor/gql-0.2.0/wandb_gql/client.py", line 52, in execute
    result = self._get_result(document, *args, **kwargs)
  File "/root/miniconda3/lib/python3.10/site-packages/wandb/vendor/gql-0.2.0/wandb_gql/client.py", line 60, in _get_result
    return self.transport.execute(document, *args, **kwargs)
  File "/root/miniconda3/lib/python3.10/site-packages/wandb/sdk/lib/gql_request.py", line 58, in execute
    request = self.session.post(self.url, **post_args)
  File "/root/miniconda3/lib/python3.10/site-packages/requests/sessions.py", line 637, in post
    return self.request("POST", url, data=data, json=json, **kwargs)
  File "/root/miniconda3/lib/python3.10/site-packages/requests/sessions.py", line 589, in request
    resp = self.send(prep, **send_kwargs)
  File "/root/miniconda3/lib/python3.10/site-packages/requests/sessions.py", line 703, in send
    r = adapter.send(request, **kwargs)
  File "/root/miniconda3/lib/python3.10/site-packages/requests/adapters.py", line 688, in send
    raise ConnectTimeout(e, request=request)
requests.exceptions.ConnectTimeout: HTTPSConnectionPool(host='api.wandb.ai', port=443): Max retries exceeded with url: /graphql (Caused by ConnectTimeoutError(<urllib3.connection.HTTPSConnection object at 0x7f2530285f60>, 'Connection to api.wandb.ai timed out. (connect timeout=20)'))
